<?xml version="1.0" ?>

<robot name="origins" xmlns:xacro="http://www.ros.org/wiki/xacro">
  <material name="red">
    <color rgba="1 0 0 1 "/>
  </material>
  <material name="blue">
    <color rgba="0 0 1 1 "/>
  </material>
  <material name="green">
    <color rgba="0 1 0 1 "/>
  </material>
  <link name="base_link">
    <visual>
      <geometry>
        <box size=" 0.15 0.15 0.46"/>
      </geometry>
      <origin rpy=" 0 0 0 " xyz=" 0 0 0.23"/>
      <material name="red"/>
    </visual>
    <collision>
      <geometry>
        <box size=" 0.15 0.15 0.46"/>
      </geometry>
    </collision>
    <inertial>
      <mass value="0.1"/>
      <inertia ixx="4.17e-4" ixy="0.0" ixz="0.0" iyy="1.75e-3" iyz="0.0" izz="2.08e-3"/>
    </inertial>
  </link>
  
  <link name="box3">
    <visual>
      <geometry>
        <box size=" 0.075 0.075 0.46"/>
      </geometry>
      <origin rpy=" 0 0 0 " xyz=" 0 0 0.23"/>
      <material name="green"/>
    </visual>
    <collision>
      <geometry>
        <box size=" 0.15 0.15 0.46"/>
      </geometry>
    </collision>
    <inertial>
      <mass value="0.1"/>
      <inertia ixx="4.17e-4" ixy="0.0" ixz="0.0" iyy="1.75e-3" iyz="0.0" izz="2.08e-3"/>
    </inertial>
  </link>
  <link name="box2">
    <visual>
      <geometry>
        <box size=" 0.075 0.075 0.46"/>
      </geometry>
      <origin rpy=" 0 0 0 " xyz=" 0 0 0.23"/>
      <material name="blue"/>
    </visual>
    <collision>
      <geometry>
        <box size=" 0.15 0.15 0.46"/>
      </geometry>
    </collision>
    <inertial>
      <mass value="0.1"/>
      <inertia ixx="4.17e-4" ixy="0.0" ixz="0.0" iyy="1.75e-3" iyz="0.0" izz="2.08e-3"/>
    </inertial>
  </link>
  <link name="box4">
    <visual>
      <geometry>
        <box size=" 0.125 0.125 0.05"/>
      </geometry>
      <origin rpy=" 0 0 0 " xyz=" 0 0 0.05"/>
      <material name="red"/>
    </visual>
    <collision>
      <geometry>
        <box size=" 0.15 0.15 0.46"/>
      </geometry>
    </collision>
    <inertial>
      <mass value="0.1"/>
      <inertia ixx="4.17e-4" ixy="0.0" ixz="0.0" iyy="1.75e-3" iyz="0.0" izz="2.08e-3"/>
    </inertial>
  </link>
  <joint name="base_box2_joint" type="revolute">
    <parent link="base_link"/>
    <child link="box2"/>
    <axis xyz="1 0 0"/>
    <limit effort="1000.0" lower="-1.57" upper="1.57" velocity="0.5"/>
    <origin rpy=" 0 0 0" xyz=" 0 0 0.5 "/>
  </joint>
  <joint name="box2_box3_joint" type="revolute">
    <parent link="box2"/>
    <child link="box3"/>
    <axis xyz="1 0 0"/>
    <limit effort="1000.0" lower="-1.57" upper="1.57" velocity="0.5"/>
    <origin rpy=" 0 0 0 " xyz=" 0 0 0.5 "/>
  </joint>
  <joint name="box3_box4_joint" type="fixed">
    <parent link="box3"/>
    <child link="box4"/>
    <origin rpy=" 0 0 0 " xyz=" 0 0 0.5 "/>
  </joint>

    <ros2_control name="GazeboSystem" type="system">
        <hardware>
            <plugin>gazebo_ros2_control/GazeboSystem</plugin>
        </hardware>
        <joint name="joint1">
            <command_interface name="position"/>
            <state_interface name="velocity"/>
            <state_interface name="position"/>
        </joint>
        <joint name="joint2">
            <command_interface name="position"/>
            <state_interface name="velocity"/>
            <state_interface name="position"/>
        </joint>
    </ros2_control>
    
    <gazebo>
        <plugin name="gazebo_ros2_control" filename="libgazebo_ros2_control.so">
            <parameters>/home/rohit/robot_arm_ws_dup/src/robot_arm/config/robot_control.yaml</parameters>  <!--Do not forget to enter the correct path or the simulation will crash without any error message-->
        </plugin>
    </gazebo> 

</robot>
